#VRML_SIM R2025a utf8

EXTERNPROTO "https://raw.githubusercontent.com/cyberbotics/webots/R2025a/projects/objects/backgrounds/protos/TexturedBackground.proto"
EXTERNPROTO "https://raw.githubusercontent.com/cyberbotics/webots/R2025a/projects/objects/backgrounds/protos/TexturedBackgroundLight.proto"
EXTERNPROTO "https://raw.githubusercontent.com/cyberbotics/webots/R2025a/projects/objects/floors/protos/RectangleArena.proto"

WorldInfo {
  info [
    "Demonstration of the alternate tripod gait using linear and rotational motors."
    "Biologically Inspired Robotics Group (BIRG)"
  ]
  title "Hexapod"
  CFM 0.0001
  ERP 0.6
  basicTimeStep 8
  contactProperties [
    ContactProperties {
      material2 "floor"
      coulombFriction [
        1.5
      ]
    }
  ]
}
Viewpoint {
  orientation 0.39372716905481336 0.7362186277804784 -0.5504189753788578 1.4437357557159638
  position 28.479283102977377 -27.032374751296043 9.16777897200325
  follow "hexapod"
}
TexturedBackground {
}
TexturedBackgroundLight {
}
RectangleArena {
  floorSize 100 100
  floorTileSize 3 3
}
DEF DELIVERY_BLOCK Solid {
  translation 30.11765637125087 -29.907136492826822 0.18
  children [
    Shape {
      appearance PBRAppearance {
        baseColor 0.96 0.42 0.35
        roughness 1
        metalness 0
      }
      geometry Box {
        size 0.18 0.5 0.18
      }
    }
  ]
  name "delivery_block"
  locked TRUE
}
DEF DELIVERY_DROP_ZONE Solid {
  translation 1.55 0.02 -1.4
  children [
    Shape {
      appearance PBRAppearance {
        baseColor 0.2 0.8 0.35
        roughness 1
        metalness 0
      }
      geometry Box {
        size 0.22 0.04 0.22
      }
    }
  ]
  name "delivery_drop_zone"
  locked TRUE
}
DEF HEXAPOD Robot {
  translation 30.118017642026455 -29.907513158540155 0.04445275193617181
  rotation -0.0005167347375132851 0.0004314150396320233 -0.9999997734331116 0.7844976924438338
  children [
    DEF compass Compass {
    }
    DEF ds_front DistanceSensor {
      translation 0.2 0.1 0.15
      name "ds_front"
      lookupTable [
        0 0 0
        1 1 0
      ]
    }
    DEF ds_left DistanceSensor {
      translation -0.15 0.1 0
      rotation 0 0 1 1.5708
      name "ds_left"
      lookupTable [
        0 0 0
        1 1 0
      ]
    }
    DEF ds_right DistanceSensor {
      translation 0.15 0.1 0
      rotation 0 0 1 -1.5708
      name "ds_right"
      lookupTable [
        0 0 0
        1 1 0
      ]
    }
    DEF ds_back DistanceSensor {
      translation 0 0.1 -0.15
      rotation 0 0 1 3.14159
      name "ds_back"
      lookupTable [
        0 0 0
        1 1 0
      ]
    }
    Display {
      width 200
      height 200
    }
    DEF HIP_HINGE_JOINT_L0 HingeJoint {
      jointParameters HingeJointParameters {
        position -0.014432532379434593
        axis 0 0 1
        anchor 0.2 0.05 0
      }
      device [
        RotationalMotor {
          name "hip_motor_l0"
          maxVelocity 5
          minPosition -0.7
          maxPosition 0.7
        }
      ]
      endPoint Solid {
        translation 0.2 0.05 0
        rotation 0 0 -1 0.014432532379434908
        children [
          DEF HIP_SHAPE Shape {
            appearance DEF HIP_APPEARANCE PBRAppearance {
              baseColor 1 0 0
              roughness 1
              metalness 0
            }
            geometry Cylinder {
              height 0.06
              radius 0.02
            }
          }
          DEF FEMUR_TRANS Pose {
            translation 0 0.06 0
            children [
              DEF FEMUR_SHAPE Shape {
                appearance DEF METAL_APPEARANCE PBRAppearance {
                  baseColor 0.5 0.5 0.5
                  roughness 1
                  metalness 0
                }
                geometry Box {
                  size 0.02 0.1 0.02
                }
              }
            ]
          }
          DEF KNEE_TRANS Pose {
            translation 0 0.11 0
            children [
              DEF KNEE_SHAPE Shape {
                appearance DEF KNEE_APPEARANCE PBRAppearance {
                  baseColor 0 0.6 0.2
                  roughness 1
                  metalness 0
                }
                geometry Cylinder {
                  height 0.06
                  radius 0.02
                }
              }
            ]
          }
          DEF KNEE_SLIDER_JOINT_L0 SliderJoint {
            jointParameters JointParameters {
              position -0.015997558436661723
              axis 0 0 -1
              minStop -0.02
              maxStop 0.02
            }
            device [
              LinearMotor {
                name "knee_motor_l0"
                minPosition -0.02
                maxPosition 0.02
                maxForce 25
              }
            ]
            endPoint Solid {
              translation 0 0.11 -0.014002441563338276
              rotation 1 0 0 1.5708
              children [
                DEF TIBIA_TRANS Pose {
                  rotation 1 0 0 1.5708
                  children [
                    DEF TIBIA_SHAPE Shape {
                      appearance USE METAL_APPEARANCE
                      geometry Cylinder {
                        height 0.06
                        radius 0.01
                      }
                    }
                  ]
                }
              ]
              boundingObject USE TIBIA_TRANS
              physics DEF STANDARD_PHYSICS Physics {
              }
              linearVelocity 0.04003542498779318 -0.04252919695018281 -0.007495166529620122
              angularVelocity -0.0001886487834256885 -2.5827777232234852e-05 -0.4001902317798917
            }
          }
        ]
        name "l0"
        boundingObject USE KNEE_TRANS
        physics USE STANDARD_PHYSICS
        linearVelocity 0.040036565393799614 -0.04252937467585966 -0.0075014422675904035
        angularVelocity -0.00018865063068730517 -2.582889945392244e-05 -0.4001902316584717
      }
    }
    DEF HIP_HINGE_JOINT_L1 HingeJoint {
      jointParameters HingeJointParameters {
        position 0.20795454183071024
        axis 0 0 1
        anchor 0 0.05 0
      }
      device [
        RotationalMotor {
          name "hip_motor_l1"
          maxVelocity 5
          minPosition -0.7
          maxPosition 0.7
        }
      ]
      endPoint Solid {
        translation 0 0.05 0
        rotation 0 0 1 0.2079545418307096
        children [
          USE HIP_SHAPE
          USE FEMUR_TRANS
          USE KNEE_TRANS
          DEF KNEE_SLIDER_JOINT_L1 SliderJoint {
            jointParameters JointParameters {
              position -0.015455975240362648
              axis 0 0 -1
              minStop -0.02
              maxStop 0.02
            }
            device [
              LinearMotor {
                name "knee_motor_l1"
                minPosition -0.02
                maxPosition 0.02
                maxForce 25
              }
            ]
            endPoint Solid {
              translation 0 0.11 -0.01454402475963735
              rotation 1 0 0 1.5708
              children [
                USE TIBIA_TRANS
              ]
              boundingObject USE TIBIA_TRANS
              physics USE STANDARD_PHYSICS
              linearVelocity -0.001109103943134637 -0.0030590221839629944 3.03297009989483e-06
              angularVelocity 4.839634356010012e-05 9.601274254839769e-05 0.12111123188438959
            }
          }
        ]
        name "l1"
        boundingObject USE KNEE_TRANS
        physics USE STANDARD_PHYSICS
        linearVelocity -0.0011426061788284351 -0.003058531727666097 -0.007483191575690176
        angularVelocity 4.863791037676098e-05 9.719350520328115e-05 0.12111096935585254
      }
    }
    DEF HIP_HINGE_JOINT_L2 HingeJoint {
      jointParameters HingeJointParameters {
        position -0.014432518918531513
        axis 0 0 1
        anchor -0.2 0.05 0
      }
      device [
        RotationalMotor {
          name "hip_motor_l2"
          maxVelocity 5
          minPosition -0.7
          maxPosition 0.7
        }
      ]
      endPoint Solid {
        translation -0.2 0.05 0
        rotation 0 0 -1 0.01443251891853881
        children [
          USE HIP_SHAPE
          USE FEMUR_TRANS
          USE KNEE_TRANS
          DEF KNEE_SLIDER_JOINT_L2 SliderJoint {
            jointParameters JointParameters {
              position -0.015997432274464395
              axis 0 0 -1
              minStop -0.02
              maxStop 0.02
            }
            device [
              LinearMotor {
                name "knee_motor_l2"
                minPosition -0.02
                maxPosition 0.02
                maxForce 25
              }
            ]
            endPoint Solid {
              translation 0 0.11 -0.014002567725535604
              rotation 1 0 0 1.5708
              children [
                USE TIBIA_TRANS
              ]
              boundingObject USE TIBIA_TRANS
              physics USE STANDARD_PHYSICS
              linearVelocity 0.041430222617862625 -0.04113189373663727 -0.0074769709293474014
              angularVelocity -0.00018866293871382852 -2.5813434668798566e-05 -0.40019037789513406
            }
          }
        ]
        name "l2"
        boundingObject USE KNEE_TRANS
        physics USE STANDARD_PHYSICS
        linearVelocity 0.04143142577302116 -0.04113200950042353 -0.007484612103113875
        angularVelocity -0.00018866435333863798 -2.5815001055508385e-05 -0.40019037777381705
      }
    }
    DEF HIP_HINGE_JOINT_R0 HingeJoint {
      jointParameters HingeJointParameters {
        position -0.2077400453500612
        axis 0 0 1
        anchor 0.2 -0.05 0
      }
      device [
        RotationalMotor {
          name "hip_motor_r0"
          maxVelocity 5
          minPosition -0.7
          maxPosition 0.7
        }
      ]
      endPoint Solid {
        translation 0.2 -0.05 0
        rotation 0 0 -0.9999999999999999 0.2077400453500612
        children [
          USE HIP_SHAPE
          DEF RIGHT_FEMUR_TRANS Pose {
            translation 0 -0.06 0
            children [
              USE FEMUR_SHAPE
            ]
          }
          DEF RIGHT_KNEE_TRANS Pose {
            translation 0 -0.11 0
            children [
              USE KNEE_SHAPE
            ]
          }
          DEF KNEE_SLIDER_JOINT_R0 SliderJoint {
            jointParameters JointParameters {
              position -0.01539660130223379
              axis 0 0 -1
              minStop -0.02
              maxStop 0.02
            }
            device [
              LinearMotor {
                name "knee_motor_r0"
                minPosition -0.02
                maxPosition 0.02
                maxForce 25
              }
            ]
            endPoint Solid {
              translation 0 -0.11 -0.01460339869776621
              rotation 1 0 0 1.5708
              children [
                USE TIBIA_TRANS
              ]
              boundingObject USE TIBIA_TRANS
              physics USE STANDARD_PHYSICS
              linearVelocity 0.0010962016384425 0.0012939185554622658 2.0201972397891414e-05
              angularVelocity -7.015857458881842e-05 3.5785417963122077e-05 -0.1311579224108895
            }
          }
        ]
        name "r0"
        boundingObject USE RIGHT_KNEE_TRANS
        physics USE STANDARD_PHYSICS
        linearVelocity 0.001075089485250904 0.0013497911963851685 -0.007484886556936672
        angularVelocity -6.801218271793404e-05 3.657648003016409e-05 -0.13115759529687362
      }
    }
    DEF HIP_HINGE_JOINT_R1 HingeJoint {
      jointParameters HingeJointParameters {
        position 0.014330023088013844
        axis 0 0 1
        anchor 0 -0.05 0
      }
      device [
        RotationalMotor {
          name "hip_motor_r1"
          maxVelocity 5
          minPosition -0.7
          maxPosition 0.7
        }
      ]
      endPoint Solid {
        translation 0 -0.05 0
        rotation 0 0 1 0.014330023088018874
        children [
          USE HIP_SHAPE
          USE RIGHT_FEMUR_TRANS
          USE RIGHT_KNEE_TRANS
          DEF KNEE_SLIDER_JOINT_R1 SliderJoint {
            jointParameters JointParameters {
              position -0.015997826023082678
              axis 0 0 -1
              minStop -0.02
              maxStop 0.02
            }
            device [
              LinearMotor {
                name "knee_motor_r1"
                minPosition -0.02
                maxPosition 0.02
                maxForce 25
              }
            ]
            endPoint Solid {
              translation 0 -0.11 -0.014002173976917314
              rotation 1 0 0 1.5708
              children [
                USE TIBIA_TRANS
              ]
              boundingObject USE TIBIA_TRANS
              physics USE STANDARD_PHYSICS
              linearVelocity 0.04039860203309667 -0.03987163757584022 -0.0074728392293690726
              angularVelocity 0.00017168370419438174 0.000162619840455114 0.38994236623173334
            }
          }
        ]
        name "r1"
        boundingObject USE RIGHT_KNEE_TRANS
        physics USE STANDARD_PHYSICS
        linearVelocity 0.04039970780290809 -0.03987175123898206 -0.00747620405339414
        angularVelocity 0.00017168236575113675 0.00016261890061556298 0.3899423660902222
      }
    }
    DEF HIP_HINGE_JOINT_R2 HingeJoint {
      jointParameters HingeJointParameters {
        position -0.2077405633043122
        axis 0 0 1
        anchor -0.2 -0.05 0
      }
      device [
        RotationalMotor {
          name "hip_motor_r2"
          maxVelocity 5
          minPosition -0.7
          maxPosition 0.7
        }
      ]
      endPoint Solid {
        translation -0.2 -0.05 0
        rotation 0 0 -1 0.20774056330431187
        children [
          USE HIP_SHAPE
          USE RIGHT_FEMUR_TRANS
          USE RIGHT_KNEE_TRANS
          DEF KNEE_SLIDER_JOINT_R2 SliderJoint {
            jointParameters JointParameters {
              position -0.01537162547805855
              axis 0 0 -1
              minStop -0.02
              maxStop 0.02
            }
            device [
              LinearMotor {
                name "knee_motor_r2"
                minPosition -0.02
                maxPosition 0.02
                maxForce 25
              }
            ]
            endPoint Solid {
              translation 0 -0.11 -0.01462837452194145
              rotation 1 0 0 1.5708
              children [
                USE TIBIA_TRANS
              ]
              boundingObject USE TIBIA_TRANS
              physics USE STANDARD_PHYSICS
              linearVelocity 0.0024560427291477455 0.002810859093851851 -1.4606789761404422e-05
              angularVelocity -6.624302409074509e-05 3.857769898657222e-05 -0.13117577014290074
            }
          }
        ]
        name "r2"
        boundingObject USE RIGHT_KNEE_TRANS
        physics USE STANDARD_PHYSICS
        linearVelocity 0.0024518761952021925 0.002807794907410846 -0.007452995009773529
        angularVelocity -6.629201669992762e-05 3.8718974104257384e-05 -0.13117576694509836
      }
    }
    DEF BODY_SHAPE Shape {
      appearance USE METAL_APPEARANCE
      geometry Box {
        size 0.48 0.1 0.05
      }
    }
    InertialUnit {
      name "imu"
    }
    GPS {
    }
    PointLight {
      attenuation 0 0 0.1
      location 0 0 3.5
      castShadows TRUE
    }
    PointLight {
      attenuation 0 0 0.1
      location -1 -1 3.5
    }
  ]
  name "hexapod"
  boundingObject USE BODY_SHAPE
  physics USE STANDARD_PHYSICS
  controller "delivery_robot"
  supervisor TRUE
  linearVelocity 0.00981994796246024 -0.010146857827481539 -0.00747794886497845
  angularVelocity -8.408424952250687e-06 6.843613979707898e-05 -0.004937103457955489
}
Solid {
  translation 23.162120091563185 -23.728534427631555 0.04990190000000001
  rotation -3.185961117101974e-17 3.617168169810052e-18 0.9999999999999999 3.0407608440726888
  boundingObject Box {
    size 0.1 0.1 0.1
  }
  physics Physics {
  }
  linearVelocity -8.833167763335513e-18 -1.1134486029977093e-17 -2.41584530158434e-16
  angularVelocity 4.930380657631324e-32 -6.66133814775094e-17 7.059869665948775e-17
}
Shape {
  appearance USE METAL_APPEARANCE
  geometry Box {
    size 0.25 0.25 0.25
  }
}
DEF OBSTACLE_SOLID_1 Solid {
  translation 23.9 -22.6 0.15
  children [
    Shape {
      appearance PBRAppearance {
        baseColor 0.95 0.15 0.15
        roughness 1
        metalness 0
      }
      geometry Box {
        size 0.3 0.3 0.3
      }
    }
  ]
  name "obstacle_solid_1"
  boundingObject Box {
    size 0.3 0.3 0.3
  }
  locked TRUE
}
