#VRML_SIM R2025a utf8

EXTERNPROTO "https://raw.githubusercontent.com/cyberbotics/webots/R2025a/projects/objects/backgrounds/protos/TexturedBackground.proto"
EXTERNPROTO "https://raw.githubusercontent.com/cyberbotics/webots/R2025a/projects/objects/backgrounds/protos/TexturedBackgroundLight.proto"
EXTERNPROTO "https://raw.githubusercontent.com/cyberbotics/webots/R2025a/projects/objects/floors/protos/RectangleArena.proto"

WorldInfo {
  info [
    "Demonstration of the alternate tripod gait using linear and rotational motors."
    "Biologically Inspired Robotics Group (BIRG)"
  ]
  title "Hexapod"
  CFM 0.0001
  ERP 0.6
  basicTimeStep 8
  contactProperties [
    ContactProperties {
      material2 "floor"
      coulombFriction [
        1.5
      ]
    }
  ]
}
Viewpoint {
  orientation -0.41940137460819826 0.25705966229418176 0.8706450579874414 2.246802620744411
  position 32.302642319798544 -28.01436250671203 10.170355282549004
  follow "hexapod"
}
TexturedBackground {
}
TexturedBackgroundLight {
}
RectangleArena {
  floorSize 100 100
  floorTileSize 3 3
}
DEF DELIVERY_BLOCK Solid {
  translation 0 -5 0
  children [
    Shape {
      appearance PBRAppearance {
        baseColor 0.96 0.42 0.35
        roughness 1
        metalness 0
      }
      geometry Box {
        size 0.18 0.5 0.18
      }
    }
  ]
  name "delivery_block"
  locked TRUE
}
DEF DELIVERY_DROP_ZONE Solid {
  translation 1.55 0.02 -1.4
  children [
    Shape {
      appearance PBRAppearance {
        baseColor 0.2 0.8 0.35
        roughness 1
        metalness 0
      }
      geometry Box {
        size 0.22 0.04 0.22
      }
    }
  ]
  name "delivery_drop_zone"
  locked TRUE
}
DEF HEXAPOD Robot {
  translation 25.89091275760809 -25.527849761723434 0.04497196918464484
  rotation -0.00034957116742410563 0.0003196476578793288 -0.9999998878126806 0.7869705914345078
  children [
    DEF compass Compass {
    }
    DEF ds_front DistanceSensor {
      translation 0.2 0.1 0.15
      name "ds_front"
      lookupTable [
        0 0 0
        1 1 0
      ]
    }
    DEF ds_left DistanceSensor {
      translation -0.15 0.1 0
      rotation 0 0 1 1.5708
      name "ds_left"
      lookupTable [
        0 0 0
        1 1 0
      ]
    }
    DEF ds_right DistanceSensor {
      translation 0.15 0.1 0
      rotation 0 0 1 -1.5708
      name "ds_right"
      lookupTable [
        0 0 0
        1 1 0
      ]
    }
    DEF ds_back DistanceSensor {
      translation 0 0.1 -0.15
      rotation 0 0 1 3.14159
      name "ds_back"
      lookupTable [
        0 0 0
        1 1 0
      ]
    }
    Display {
      width 200
      height 200
    }
    DEF HIP_HINGE_JOINT_L0 HingeJoint {
      jointParameters HingeJointParameters {
        position -0.013869428544990254
        axis 0 0 1
        anchor 0.2 0.05 0
      }
      device [
        RotationalMotor {
          name "hip_motor_l0"
          maxVelocity 5
          minPosition -0.7
          maxPosition 0.7
        }
      ]
      endPoint Solid {
        translation 0.2 0.05 0
        rotation 0 0 -1 0.013869428544995557
        children [
          DEF HIP_SHAPE Shape {
            appearance DEF HIP_APPEARANCE PBRAppearance {
              baseColor 1 0 0
              roughness 1
              metalness 0
            }
            geometry Cylinder {
              height 0.06
              radius 0.02
            }
          }
          DEF FEMUR_TRANS Pose {
            translation 0 0.06 0
            children [
              DEF FEMUR_SHAPE Shape {
                appearance DEF METAL_APPEARANCE PBRAppearance {
                  baseColor 0.5 0.5 0.5
                  roughness 1
                  metalness 0
                }
                geometry Box {
                  size 0.02 0.1 0.02
                }
              }
            ]
          }
          DEF KNEE_TRANS Pose {
            translation 0 0.11 0
            children [
              DEF KNEE_SHAPE Shape {
                appearance DEF KNEE_APPEARANCE PBRAppearance {
                  baseColor 0 0.6 0.2
                  roughness 1
                  metalness 0
                }
                geometry Cylinder {
                  height 0.06
                  radius 0.02
                }
              }
            ]
          }
          DEF KNEE_SLIDER_JOINT_L0 SliderJoint {
            jointParameters JointParameters {
              position -0.015967094883273452
              axis 0 0 -1
              minStop -0.02
              maxStop 0.02
            }
            device [
              LinearMotor {
                name "knee_motor_l0"
                minPosition -0.02
                maxPosition 0.02
                maxForce 25
              }
            ]
            endPoint Solid {
              translation 0 0.11 -0.014032905116726547
              rotation 1 0 0 1.5708
              children [
                DEF TIBIA_TRANS Pose {
                  rotation 1 0 0 1.5708
                  children [
                    DEF TIBIA_SHAPE Shape {
                      appearance USE METAL_APPEARANCE
                      geometry Cylinder {
                        height 0.06
                        radius 0.01
                      }
                    }
                  ]
                }
              ]
              boundingObject USE TIBIA_TRANS
              physics DEF STANDARD_PHYSICS Physics {
              }
              linearVelocity -0.06193795013770971 0.06437347783562017 0.019261002543042503
              angularVelocity -0.0014281812696103676 0.0013234869562256538 0.3708572781423042
            }
          }
        ]
        name "l0"
        boundingObject USE KNEE_TRANS
        physics USE STANDARD_PHYSICS
        linearVelocity -0.061916578570443886 0.0643916635286216 0.018923394129419246
        angularVelocity -0.0014282061397017348 0.0013234626375127488 0.3708572752322296
      }
    }
    DEF HIP_HINGE_JOINT_L1 HingeJoint {
      jointParameters HingeJointParameters {
        position 0.1675556559101368
        axis 0 0 1
        anchor 0 0.05 0
      }
      device [
        RotationalMotor {
          name "hip_motor_l1"
          maxVelocity 5
          minPosition -0.7
          maxPosition 0.7
        }
      ]
      endPoint Solid {
        translation 0 0.05 0
        rotation 0 0 0.9999999999999999 0.1675556559101359
        children [
          USE HIP_SHAPE
          USE FEMUR_TRANS
          USE KNEE_TRANS
          DEF KNEE_SLIDER_JOINT_L1 SliderJoint {
            jointParameters JointParameters {
              position -0.014928061689772516
              axis 0 0 -1
              minStop -0.02
              maxStop 0.02
            }
            device [
              LinearMotor {
                name "knee_motor_l1"
                minPosition -0.02
                maxPosition 0.02
                maxForce 25
              }
            ]
            endPoint Solid {
              translation 0 0.11 -0.015071938310227483
              rotation 1 -1.4203132455194153e-13 2.1047054586863924e-13 1.570799999998761
              children [
                USE TIBIA_TRANS
              ]
              boundingObject USE TIBIA_TRANS
              physics USE STANDARD_PHYSICS
              linearVelocity 0.0037432154723836307 0.005384041985347593 -0.0003367066660406973
              angularVelocity -0.0017283496062760013 0.0012010102041956432 -0.4308411595790168
            }
          }
        ]
        name "l1"
        boundingObject USE KNEE_TRANS
        physics USE STANDARD_PHYSICS
        linearVelocity 0.003629487198105682 0.0057006903680400945 0.018777545052242085
        angularVelocity -0.0017170379718465458 0.0012062308951370326 -0.4308388726828323
      }
    }
    DEF HIP_HINGE_JOINT_L2 HingeJoint {
      jointParameters HingeJointParameters {
        position -0.01386982351826203
        axis 0 0 1
        anchor -0.2 0.05 0
      }
      device [
        RotationalMotor {
          name "hip_motor_l2"
          maxVelocity 5
          minPosition -0.7
          maxPosition 0.7
        }
      ]
      endPoint Solid {
        translation -0.2 0.05 0
        rotation 0 0 -1 0.013869823518274383
        children [
          USE HIP_SHAPE
          USE FEMUR_TRANS
          USE KNEE_TRANS
          DEF KNEE_SLIDER_JOINT_L2 SliderJoint {
            jointParameters JointParameters {
              position -0.015968735415702606
              axis 0 0 -1
              minStop -0.02
              maxStop 0.02
            }
            device [
              LinearMotor {
                name "knee_motor_l2"
                minPosition -0.02
                maxPosition 0.02
                maxForce 25
              }
            ]
            endPoint Solid {
              translation 0 0.11 -0.014031264584297393
              rotation 1 0 0 1.5708
              children [
                USE TIBIA_TRANS
              ]
              boundingObject USE TIBIA_TRANS
              physics USE STANDARD_PHYSICS
              linearVelocity -0.06516811841281968 0.061154699562901045 0.019165623175963487
              angularVelocity -0.0014280276748924463 0.0013233310856211639 0.37086157697424416
            }
          }
        ]
        name "l2"
        boundingObject USE KNEE_TRANS
        physics USE STANDARD_PHYSICS
        linearVelocity -0.06514699324212307 0.061172618914457313 0.01884556421079956
        angularVelocity -0.0014280531405196392 0.001323306701718663 0.37086157394897784
      }
    }
    DEF HIP_HINGE_JOINT_R0 HingeJoint {
      jointParameters HingeJointParameters {
        position -0.16755446622071204
        axis 0 0 1
        anchor 0.2 -0.05 0
      }
      device [
        RotationalMotor {
          name "hip_motor_r0"
          maxVelocity 5
          minPosition -0.7
          maxPosition 0.7
        }
      ]
      endPoint Solid {
        translation 0.2 -0.05 0
        rotation 0 0 -1 0.16755446622071296
        children [
          USE HIP_SHAPE
          DEF RIGHT_FEMUR_TRANS Pose {
            translation 0 -0.06 0
            children [
              USE FEMUR_SHAPE
            ]
          }
          DEF RIGHT_KNEE_TRANS Pose {
            translation 0 -0.11 0
            children [
              USE KNEE_SHAPE
            ]
          }
          DEF KNEE_SLIDER_JOINT_R0 SliderJoint {
            jointParameters JointParameters {
              position -0.01490200177121846
              axis 0 0 -1
              minStop -0.02
              maxStop 0.02
            }
            device [
              LinearMotor {
                name "knee_motor_r0"
                minPosition -0.02
                maxPosition 0.02
                maxForce 25
              }
            ]
            endPoint Solid {
              translation 0 -0.11 -0.015097998228781538
              rotation 1 -2.325712052244128e-13 7.468779262358858e-14 1.5707999999989197
              children [
                USE TIBIA_TRANS
              ]
              boundingObject USE TIBIA_TRANS
              physics USE STANDARD_PHYSICS
              linearVelocity -0.003692483962051612 -0.006592390383389346 -3.147358725144318e-05
              angularVelocity -0.0013958355426190454 0.001312952121494953 0.4536280564571793
            }
          }
        ]
        name "r0"
        boundingObject USE RIGHT_KNEE_TRANS
        physics USE STANDARD_PHYSICS
        linearVelocity -0.003826508291388 -0.006561376603281705 0.019443477056556305
        angularVelocity -0.0013957083148924809 0.001319169201220713 0.4536262759752278
      }
    }
    DEF HIP_HINGE_JOINT_R1 HingeJoint {
      jointParameters HingeJointParameters {
        position 0.013868807118010362
        axis 0 0 1
        anchor 0 -0.05 0
      }
      device [
        RotationalMotor {
          name "hip_motor_r1"
          maxVelocity 5
          minPosition -0.7
          maxPosition 0.7
        }
      ]
      endPoint Solid {
        translation 0 -0.05 0
        rotation 0 0 1 0.013868807117997307
        children [
          USE HIP_SHAPE
          USE RIGHT_FEMUR_TRANS
          USE RIGHT_KNEE_TRANS
          DEF KNEE_SLIDER_JOINT_R1 SliderJoint {
            jointParameters JointParameters {
              position -0.015983526502074425
              axis 0 0 -1
              minStop -0.02
              maxStop 0.02
            }
            device [
              LinearMotor {
                name "knee_motor_r1"
                minPosition -0.02
                maxPosition 0.02
                maxForce 25
              }
            ]
            endPoint Solid {
              translation 0 -0.11 -0.014016473497925567
              rotation 1 0 0 1.5708
              children [
                USE TIBIA_TRANS
              ]
              boundingObject USE TIBIA_TRANS
              physics USE STANDARD_PHYSICS
              linearVelocity -0.06183518508261915 0.059324542914150714 0.01968280988241832
              angularVelocity -0.001669249514026145 0.0012191086301912954 -0.34803728831298403
            }
          }
        ]
        name "r1"
        boundingObject USE RIGHT_KNEE_TRANS
        physics USE STANDARD_PHYSICS
        linearVelocity -0.06181348338448978 0.05934262490152058 0.019523527603835765
        angularVelocity -0.0016692702905387945 0.0012190804733691607 -0.3480372860470437
      }
    }
    DEF HIP_HINGE_JOINT_R2 HingeJoint {
      jointParameters HingeJointParameters {
        position -0.16755352946965582
        axis 0 0 1
        anchor -0.2 -0.05 0
      }
      device [
        RotationalMotor {
          name "hip_motor_r2"
          maxVelocity 5
          minPosition -0.7
          maxPosition 0.7
        }
      ]
      endPoint Solid {
        translation -0.2 -0.05 0
        rotation 0 0 -1 0.1675535294696553
        children [
          USE HIP_SHAPE
          USE RIGHT_FEMUR_TRANS
          USE RIGHT_KNEE_TRANS
          DEF KNEE_SLIDER_JOINT_R2 SliderJoint {
            jointParameters JointParameters {
              position -0.014884674148480848
              axis 0 0 -1
              minStop -0.02
              maxStop 0.02
            }
            device [
              LinearMotor {
                name "knee_motor_r2"
                minPosition -0.02
                maxPosition 0.02
                maxForce 25
              }
            ]
            endPoint Solid {
              translation 0 -0.11 -0.015115325851519151
              rotation 1 -2.3380528150137374e-13 7.284186406947634e-14 1.5707999999989226
              children [
                USE TIBIA_TRANS
              ]
              boundingObject USE TIBIA_TRANS
              physics USE STANDARD_PHYSICS
              linearVelocity -0.007181559255147352 -0.009862133144885628 -9.239425413652387e-05
              angularVelocity -0.0014049994747910247 0.0013338395259077998 0.453639054820383
            }
          }
        ]
        name "r2"
        boundingObject USE RIGHT_KNEE_TRANS
        physics USE STANDARD_PHYSICS
        linearVelocity -0.007185752307984112 -0.00980690787180756 0.019477398691843346
        angularVelocity -0.0014039157770306448 0.0013351346241029802 0.45363859663367023
      }
    }
    DEF BODY_SHAPE Shape {
      appearance USE METAL_APPEARANCE
      geometry Box {
        size 0.48 0.1 0.05
      }
    }
    InertialUnit {
      name "imu"
    }
    GPS {
    }
    PointLight {
      attenuation 0 0 0.1
      location 0 0 3.5
      castShadows TRUE
    }
    PointLight {
      attenuation 0 0 0.1
      location -1 -1 3.5
    }
  ]
  name "hexapod"
  boundingObject USE BODY_SHAPE
  physics USE STANDARD_PHYSICS
  controller "delivery_robot"
  supervisor TRUE
  linearVelocity -0.03475883937982712 0.03302801350874984 0.019192503129498426
  angularVelocity -0.001548702414862984 0.0012711361996077374 0.011406752475359612
}
Solid {
  translation 23.162120091563185 -23.728534427631555 0.04990190000000001
  rotation 1.4696911499328667e-18 -4.444164310571165e-19 1 3.0407608440726888
  boundingObject Box {
    size 0.1 0.1 0.1
  }
  physics Physics {
  }
  linearVelocity 8.298170308994515e-19 6.760734340196733e-18 -2.55795384873636e-16
  angularVelocity -5.7931972727168054e-30 1.332267629550157e-16 1.7719507928598666e-17
}
Shape {
  appearance USE METAL_APPEARANCE
  geometry Box {
    size 0.25 0.25 0.25
  }
}
DEF OBSTACLE_SOLID_1 Solid {
  translation 24.7 -2 0.15
  children [
    Shape {
      appearance PBRAppearance {
        baseColor 0.95 0.15 0.15
        roughness 1
        metalness 0
      }
      geometry Box {
        size 0.3 0.3 0.3
      }
    }
  ]
  name "obstacle_solid_1"
  boundingObject Box {
    size 0.3 0.3 0.3
  }
  locked TRUE
}
