#VRML_SIM R2025a utf8

EXTERNPROTO "https://raw.githubusercontent.com/cyberbotics/webots/R2025a/projects/objects/backgrounds/protos/TexturedBackground.proto"
EXTERNPROTO "https://raw.githubusercontent.com/cyberbotics/webots/R2025a/projects/objects/backgrounds/protos/TexturedBackgroundLight.proto"
EXTERNPROTO "https://raw.githubusercontent.com/cyberbotics/webots/R2025a/projects/objects/floors/protos/RectangleArena.proto"

WorldInfo {
  info [
    "Demonstration of the alternate tripod gait using linear and rotational motors."
    "Biologically Inspired Robotics Group (BIRG)"
  ]
  title "Hexapod"
  CFM 0.0001
  ERP 0.6
  basicTimeStep 8
  contactProperties [
    ContactProperties {
      material2 "floor"
      coulombFriction [
        1.5
      ]
    }
  ]
}
Viewpoint {
  orientation 0.05934006147270911 -0.24638769987751277 -0.9673530164595981 5.43165200675038
  position 0.7628131935329328 -11.04292007191866 -0.11640459412988347
  follow "hexapod"
}
TexturedBackground {
}
TexturedBackgroundLight {
}
RectangleArena {
  floorSize 50 50
  floorTileSize 3 3
}
DEF DELIVERY_BLOCK Solid {
  translation 3.95 0.09 0.1
  children [
    Shape {
      appearance PBRAppearance {
        baseColor 0.96 0.42 0.35
        roughness 1
        metalness 0
      }
      geometry Box {
        size 0.18 0.5 0.18
      }
    }
  ]
  name "delivery_block"
  locked TRUE
}
DEF DELIVERY_DROP_ZONE Solid {
  translation 1.55 0.02 -1.40
  children [
    Shape {
      appearance PBRAppearance {
        baseColor 0.20 0.80 0.35
        roughness 1
        metalness 0
      }
      geometry Box {
        size 0.22 0.04 0.22
      }
    }
  ]
  name "delivery_drop_zone"
  locked TRUE
}
DEF HEXAPOD Robot {
  supervisor TRUE
  translation 2.60 0.06 -0.55
  rotation 0 1 0 0
  children [
    DEF HIP_HINGE_JOINT_L0 HingeJoint {
      jointParameters HingeJointParameters {
        position 0.09195599720742895
        axis 0 0 1
        anchor 0.2 0.05 0
      }
      device [
        RotationalMotor {
          name "hip_motor_l0"
          maxVelocity 5
          minPosition -0.7
          maxPosition 0.7
        }
      ]
      endPoint Solid {
        translation 0.2 0.05 0
        rotation 0 0 1 0.09195599720743051
        children [
          DEF HIP_SHAPE Shape {
            appearance DEF HIP_APPEARANCE PBRAppearance {
              baseColor 1 0 0
              roughness 1
              metalness 0
            }
            geometry Cylinder {
              height 0.06
              radius 0.02
            }
          }
          DEF FEMUR_TRANS Pose {
            translation 0 0.06 0
            children [
              DEF FEMUR_SHAPE Shape {
                appearance DEF METAL_APPEARANCE PBRAppearance {
                  baseColor 0.5 0.5 0.5
                  roughness 1
                  metalness 0
                }
                geometry Box {
                  size 0.02 0.1 0.02
                }
              }
            ]
          }
          DEF KNEE_TRANS Pose {
            translation 0 0.11 0
            children [
              DEF KNEE_SHAPE Shape {
                appearance DEF KNEE_APPEARANCE PBRAppearance {
                  baseColor 0 0.6 0.2
                  roughness 1
                  metalness 0
                }
                geometry Cylinder {
                  height 0.06
                  radius 0.02
                }
              }
            ]
          }
          DEF KNEE_SLIDER_JOINT_L0 SliderJoint {
            jointParameters JointParameters {
              position -0.011960673572354773
              axis 0 0 -1
              minStop -0.02
              maxStop 0.02
            }
            device [
              LinearMotor {
                name "knee_motor_l0"
                minPosition -0.02
                maxPosition 0.02
                maxForce 25
              }
            ]
            endPoint Solid {
              translation 0 0.11 -0.018039326427645226
              rotation 1 0 0 1.5708
              children [
                DEF TIBIA_TRANS Pose {
                  rotation 1 0 0 1.5708
                  children [
                    DEF TIBIA_SHAPE Shape {
                      appearance USE METAL_APPEARANCE
                      geometry Cylinder {
                        height 0.06
                        radius 0.01
                      }
                    }
                  ]
                }
              ]
              boundingObject USE TIBIA_TRANS
              physics DEF STANDARD_PHYSICS Physics {
              }
              linearVelocity 0.027906001821515578 -0.08308719335206083 0.028787646259805108
              angularVelocity -0.00131990418611542 0.0021782590231364356 -0.4094929358674948
            }
          }
        ]
        name "l0"
        boundingObject USE KNEE_TRANS
        physics USE STANDARD_PHYSICS
        linearVelocity 0.02794976705492824 -0.08308706077163941 0.02838013509644882
        angularVelocity -0.0013199042077719297 0.0021782590113643926 -0.4094929358678394
      }
    }
    DEF HIP_HINGE_JOINT_L1 HingeJoint {
      jointParameters HingeJointParameters {
        position 0.14803976627943755
        axis 0 0 1
        anchor 0 0.05 0
      }
      device [
        RotationalMotor {
          name "hip_motor_l1"
          maxVelocity 5
          minPosition -0.7
          maxPosition 0.7
        }
      ]
      endPoint Solid {
        translation 0 0.05 0
        rotation 0 0 1 0.14803976627943716
        children [
          USE HIP_SHAPE
          USE FEMUR_TRANS
          USE KNEE_TRANS
          DEF KNEE_SLIDER_JOINT_L1 SliderJoint {
            jointParameters JointParameters {
              position 0.00746729150421746
              axis 0 0 -1
              minStop -0.02
              maxStop 0.02
            }
            device [
              LinearMotor {
                name "knee_motor_l1"
                minPosition -0.02
                maxPosition 0.02
                maxForce 25
              }
            ]
            endPoint Solid {
              translation 0 0.11 -0.03746729150421746
              rotation 1 0 0 1.5708
              children [
                USE TIBIA_TRANS
              ]
              boundingObject USE TIBIA_TRANS
              physics USE STANDARD_PHYSICS
              linearVelocity -0.005520223328172328 -0.0020115488723599795 -3.1801577627679586e-06
              angularVelocity 0.0012071286390810238 0.0027990647128138257 0.38957072564138817
            }
          }
        ]
        name "l1"
        boundingObject USE KNEE_TRANS
        physics USE STANDARD_PHYSICS
        linearVelocity -0.005341842903130081 -0.0019970359724052326 0.028567361178280702
        angularVelocity 0.0012069816232215804 0.0027997408914512863 0.3895706126280724
      }
    }
    DEF HIP_HINGE_JOINT_L2 HingeJoint {
      jointParameters HingeJointParameters {
        position 0.09195599567616912
        axis 0 0 1
        anchor -0.2 0.05 0
      }
      device [
        RotationalMotor {
          name "hip_motor_l2"
          maxVelocity 5
          minPosition -0.7
          maxPosition 0.7
        }
      ]
      endPoint Solid {
        translation -0.2 0.05 0
        rotation 0 0 0.9999999999999999 0.09195599567617023
        children [
          USE HIP_SHAPE
          USE FEMUR_TRANS
          USE KNEE_TRANS
          DEF KNEE_SLIDER_JOINT_L2 SliderJoint {
            jointParameters JointParameters {
              position -0.011958365354762449
              axis 0 0 -1
              minStop -0.02
              maxStop 0.02
            }
            device [
              LinearMotor {
                name "knee_motor_l2"
                minPosition -0.02
                maxPosition 0.02
                maxForce 25
              }
            ]
            endPoint Solid {
              translation 0 0.11 -0.01804163464523755
              rotation 1 0 0 1.5708
              children [
                USE TIBIA_TRANS
              ]
              boundingObject USE TIBIA_TRANS
              physics USE STANDARD_PHYSICS
              linearVelocity 0.031725630563209685 -0.08193525365403145 0.029078593033656525
              angularVelocity -0.001319904075238843 0.0021782589034098393 -0.40949292244506263
            }
          }
        ]
        name "l2"
        boundingObject USE KNEE_TRANS
        physics USE STANDARD_PHYSICS
        linearVelocity 0.03176932606685123 -0.08193513918815037 0.028645992718249604
        angularVelocity -0.0013199040878977446 0.0021782588572395642 -0.4094929224454048
      }
    }
    DEF HIP_HINGE_JOINT_R0 HingeJoint {
      jointParameters HingeJointParameters {
        position -0.14927548544162558
        axis 0 0 1
        anchor 0.2 -0.05 0
      }
      device [
        RotationalMotor {
          name "hip_motor_r0"
          maxVelocity 5
          minPosition -0.7
          maxPosition 0.7
        }
      ]
      endPoint Solid {
        translation 0.2 -0.05 0
        rotation 0 0 -1 0.14927548544162542
        children [
          USE HIP_SHAPE
          DEF RIGHT_FEMUR_TRANS Pose {
            translation 0 -0.06 0
            children [
              USE FEMUR_SHAPE
            ]
          }
          DEF RIGHT_KNEE_TRANS Pose {
            translation 0 -0.11 0
            children [
              USE KNEE_SHAPE
            ]
          }
          DEF KNEE_SLIDER_JOINT_R0 SliderJoint {
            jointParameters JointParameters {
              position 0.008398920513525839
              axis 0 0 -1
              minStop -0.02
              maxStop 0.02
            }
            device [
              LinearMotor {
                name "knee_motor_r0"
                minPosition -0.02
                maxPosition 0.02
                maxForce 25
              }
            ]
            endPoint Solid {
              translation 0 -0.11 -0.038398920513525836
              rotation 1 0 0 1.5708
              children [
                USE TIBIA_TRANS
              ]
              boundingObject USE TIBIA_TRANS
              physics USE STANDARD_PHYSICS
              linearVelocity 0.004175222575609552 0.002676587516045867 -3.0348061383626567e-05
              angularVelocity -0.0012782682395262525 0.0021904947143560416 -0.3960868566603455
            }
          }
        ]
        name "r0"
        boundingObject USE RIGHT_KNEE_TRANS
        physics USE STANDARD_PHYSICS
        linearVelocity 0.004372285438655397 0.002700951378585794 0.029159668060794033
        angularVelocity -0.00127798486483808 0.0021899740308724837 -0.3960868333009579
      }
    }
    DEF HIP_HINGE_JOINT_R1 HingeJoint {
      jointParameters HingeJointParameters {
        position -0.08767358168670351
        axis 0 0 1
        anchor 0 -0.05 0
      }
      device [
        RotationalMotor {
          name "hip_motor_r1"
          maxVelocity 5
          minPosition -0.7
          maxPosition 0.7
        }
      ]
      endPoint Solid {
        translation 0 -0.05 0
        rotation 0 0 -1 0.08767358168670412
        children [
          USE HIP_SHAPE
          USE RIGHT_FEMUR_TRANS
          USE RIGHT_KNEE_TRANS
          DEF KNEE_SLIDER_JOINT_R1 SliderJoint {
            jointParameters JointParameters {
              position -0.011966502031455018
              axis 0 0 -1
              minStop -0.02
              maxStop 0.02
            }
            device [
              LinearMotor {
                name "knee_motor_r1"
                minPosition -0.02
                maxPosition 0.02
                maxForce 25
              }
            ]
            endPoint Solid {
              translation 0 -0.11 -0.018033497968544976
              rotation 1 0 0 1.5708
              children [
                USE TIBIA_TRANS
              ]
              boundingObject USE TIBIA_TRANS
              physics USE STANDARD_PHYSICS
              linearVelocity 0.020187192823489006 -0.07678358805095638 0.029648098593529227
              angularVelocity 0.0010593832499032885 0.0027645379537043356 0.3429983979076609
            }
          }
        ]
        name "r1"
        boundingObject USE RIGHT_KNEE_TRANS
        physics USE STANDARD_PHYSICS
        linearVelocity 0.020231142570468492 -0.07678338688052411 0.029303940662564115
        angularVelocity 0.0010593834127663013 0.002764537955045895 0.34299839789923126
      }
    }
    DEF HIP_HINGE_JOINT_R2 HingeJoint {
      jointParameters HingeJointParameters {
        position -0.1492741587547669
        axis 0 0 1
        anchor -0.2 -0.05 0
      }
      device [
        RotationalMotor {
          name "hip_motor_r2"
          maxVelocity 5
          minPosition -0.7
          maxPosition 0.7
        }
      ]
      endPoint Solid {
        translation -0.2 -0.05 0
        rotation 0 0 -1 0.1492741587547661
        children [
          USE HIP_SHAPE
          USE RIGHT_FEMUR_TRANS
          USE RIGHT_KNEE_TRANS
          DEF KNEE_SLIDER_JOINT_R2 SliderJoint {
            jointParameters JointParameters {
              position 0.008446762587729638
              axis 0 0 -1
              minStop -0.02
              maxStop 0.02
            }
            device [
              LinearMotor {
                name "knee_motor_r2"
                minPosition -0.02
                maxPosition 0.02
                maxForce 25
              }
            ]
            endPoint Solid {
              translation 0 -0.11 -0.03844676258772964
              rotation 1 0 0 1.5708
              children [
                USE TIBIA_TRANS
              ]
              boundingObject USE TIBIA_TRANS
              physics USE STANDARD_PHYSICS
              linearVelocity 0.00801992383098887 0.00381577460313071 3.266280584357534e-05
              angularVelocity -0.0012788822672579773 0.0021879710908708117 -0.3960961141016492
            }
          }
        ]
        name "r2"
        boundingObject USE RIGHT_KNEE_TRANS
        physics USE STANDARD_PHYSICS
        linearVelocity 0.008204682045040176 0.003847199820723612 0.029417137568623984
        angularVelocity -0.0012783008961133558 0.002188125418113839 -0.3960959877272176
      }
    }
    DEF BODY_SHAPE Shape {
      appearance USE METAL_APPEARANCE
      geometry Box {
        size 0.48 0.1 0.05
      }
    }
    InertialUnit {
      name "imu"
    }
    GPS {
      name "gps"
    }
    PointLight {
      attenuation 0 0 0.1
      location 0 0 3.5
      castShadows TRUE
    }
    PointLight {
      attenuation 0 0 0.1
      location -1 -1 3.5
    }
  ]
  name "hexapod"
  boundingObject USE BODY_SHAPE
  physics USE STANDARD_PHYSICS
  controller "hexapod"
  linearVelocity 0.012738282598754796 -0.040311224734095576 0.028909722629147493
  angularVelocity -5.6632511073983544e-05 0.0024895136542883787 -0.00997334972492835
}
