#VRML_SIM R2025a utf8

EXTERNPROTO "https://raw.githubusercontent.com/cyberbotics/webots/R2025a/projects/objects/backgrounds/protos/TexturedBackground.proto"
EXTERNPROTO "https://raw.githubusercontent.com/cyberbotics/webots/R2025a/projects/objects/backgrounds/protos/TexturedBackgroundLight.proto"
EXTERNPROTO "https://raw.githubusercontent.com/cyberbotics/webots/R2025a/projects/objects/floors/protos/RectangleArena.proto"

WorldInfo {
  title "Legged Robot"
  basicTimeStep 20
  contactProperties [
    ContactProperties {
      material1 "default"
      material2 "default"
      coulombFriction [ 3.0 ]
      bounce 0
    }
  ]
}
Viewpoint {
  orientation -0.20346068281237709 0.06978209244984604 0.9765931651014369 2.4952007544459214
  position 1.8800310218971341 -2.40737278764777 0.9343194064791224
}
TexturedBackground {
}
TexturedBackgroundLight {
}
RectangleArena {
  floorSize 10 10
  floorTileSize 1 1
  wallHeight 0.5
}
DEF QUADRUPED Robot {
  supervisor TRUE
  translation 0 0.31 0
  rotation 0 1 0 0
  children [
    DEF BODY Solid {
      children [
        Shape {
          appearance PBRAppearance {
            baseColor 0.2 0.4 0.8
            roughness 0.5
            metalness 0.3
          }
          geometry Box {
            size 0.4 0.08 0.2
          }
        }
      ]
      name "body"
      boundingObject Box {
        size 0.4 0.08 0.2
      }
      physics Physics {
        density -1
        mass 1
      }
    }
    DEF FL_HIP HingeJoint {
      jointParameters HingeJointParameters {
        position -0.2537934755614147
        axis 0 0 1
        anchor 0.15 -0.04 0.09
      }
      device [
        RotationalMotor {
          name "fl_hip"
          maxVelocity 6
          maxTorque 20
          minPosition -0.8
          maxPosition 0.8
        }
        PositionSensor {
          name "fl_hip_sensor"
        }
      ]
      endPoint Solid {
        translation 0.13242455988657212 -0.10775768520853773 0.09
        rotation 0 0 -1 0.25379347556141435
        children [
          Shape {
            appearance PBRAppearance {
              baseColor 0.8 0.3 0.1
            }
            geometry Box {
              size 0.03 0.14 0.03
            }
          }
          DEF FL_KNEE HingeJoint {
            jointParameters HingeJointParameters {
              position -0.866443153118305
              axis 0 0 1
              anchor 0 -0.07 0
            }
            device [
              RotationalMotor {
                name "fl_knee"
                maxVelocity 6
                maxTorque 20
                minPosition -1.5
                maxPosition 0.1
              }
              PositionSensor {
                name "fl_knee_sensor"
              }
            ]
            endPoint Solid {
              translation -0.053342139042436024 -0.11532787445245385 0
              rotation 0 0 -1 0.8664431531183052
              children [
                Shape {
                  appearance PBRAppearance {
                    baseColor 0.9 0.6 0.1
                  }
                  geometry Box {
                    size 0.025 0.14 0.025
                  }
                }
              ]
              name "fl_shin"
              boundingObject Box {
                size 0.04 0.16 0.04
              }
              physics Physics {
                density -1
                mass 0.15
              }
              linearVelocity -0.19065918054803055 0.18571094621242284 -0.0006858066622287615
              angularVelocity -0.0008027649447097131 -0.009112834277750248 -2.0917177938676064
            }
          }
        ]
        name "fl_thigh"
        boundingObject Box {
          size 0.03 0.14 0.03
        }
        physics Physics {
          density -1
          mass 0.15
        }
        linearVelocity -0.06592002607813442 0.02950529712456927 -6.381515091684755e-05
        angularVelocity -0.0005927408613704199 -0.0045181640602608 -1.001771996578836
      }
    }
    DEF FR_HIP HingeJoint {
      jointParameters HingeJointParameters {
        position 0.17163778800302565
        axis 0 0 1
        anchor 0.15 -0.04 -0.09
      }
      device [
        RotationalMotor {
          name "fr_hip"
          maxVelocity 6
          maxTorque 20
          minPosition -0.8
          maxPosition 0.8
        }
        PositionSensor {
          name "fr_hip_sensor"
        }
      ]
      endPoint Solid {
        translation 0.1619557410244668 -0.10897144522594754 -0.09
        rotation 0 0 1 0.17163778800302612
        children [
          Shape {
            appearance PBRAppearance {
              baseColor 0.8 0.3 0.1
            }
            geometry Box {
              size 0.03 0.14 0.03
            }
          }
          DEF FR_KNEE HingeJoint {
            jointParameters HingeJointParameters {
              position -1.098863473109572
              axis 0 0 1
              anchor 0 -0.07 0
            }
            device [
              RotationalMotor {
                name "fr_knee"
                maxVelocity 6
                maxTorque 20
                minPosition -1.5
                maxPosition 0.1
              }
              PositionSensor {
                name "fr_knee_sensor"
              }
            ]
            endPoint Solid {
              translation -0.06234838822798365 -0.1018226096568561 0
              rotation 0 0 -1 1.0988634731095723
              children [
                Shape {
                  appearance PBRAppearance {
                    baseColor 0.9 0.6 0.1
                  }
                  geometry Box {
                    size 0.025 0.14 0.025
                  }
                }
              ]
              name "fr_shin"
              boundingObject Box {
                size 0.04 0.16 0.04
              }
              physics Physics {
                density -1
                mass 0.15
              }
              linearVelocity -0.09321137674796726 0.03168032574737672 -3.172552232238475e-05
              angularVelocity -0.0005048066132523683 -0.0025762163177505937 -0.5406461910240151
            }
          }
        ]
        name "fr_thigh"
        boundingObject Box {
          size 0.03 0.14 0.03
        }
        physics Physics {
          density -1
          mass 0.15
        }
        linearVelocity -0.035877404458058225 0.003810551510698984 4.662964815949544e-05
        angularVelocity -0.0005022429097055099 -0.0025193392189274935 -0.5271162768314425
      }
    }
    DEF BL_HIP HingeJoint {
      jointParameters HingeJointParameters {
        position 0.11333717161538942
        axis 0 0 1
        anchor -0.15 -0.04 0.09
      }
      device [
        RotationalMotor {
          name "bl_hip"
          maxVelocity 6
          maxTorque 20
          minPosition -0.8
          maxPosition 0.8
        }
        PositionSensor {
          name "bl_hip_sensor"
        }
      ]
      endPoint Solid {
        translation -0.14208337201687268 -0.10955089504367829 0.09
        rotation 0 0 1 0.11333717161539103
        children [
          Shape {
            appearance PBRAppearance {
              baseColor 0.8 0.3 0.1
            }
            geometry Box {
              size 0.03 0.14 0.03
            }
          }
          DEF BL_KNEE HingeJoint {
            jointParameters HingeJointParameters {
              position -1.0988634723888702
              axis 0 0 1
              anchor 0 -0.07 0
            }
            device [
              RotationalMotor {
                name "bl_knee"
                maxVelocity 6
                maxTorque 20
                minPosition -1.5
                maxPosition 0.1
              }
              PositionSensor {
                name "bl_knee_sensor"
              }
            ]
            endPoint Solid {
              translation -0.06234838820504902 -0.10182260970179073 0
              rotation 0 0 -1 1.0988634723888704
              children [
                Shape {
                  appearance PBRAppearance {
                    baseColor 0.9 0.6 0.1
                  }
                  geometry Box {
                    size 0.025 0.14 0.025
                  }
                }
              ]
              name "bl_shin"
              boundingObject Box {
                size 0.04 0.16 0.04
              }
              physics Physics {
                density -1
                mass 0.15
              }
              linearVelocity -0.09336589206325767 0.014557882780004184 -6.0463664867072036e-05
              angularVelocity -0.0005050978250617964 -0.0025769194962295735 -0.5408057553938163
            }
          }
        ]
        name "bl_thigh"
        boundingObject Box {
          size 0.03 0.14 0.03
        }
        physics Physics {
          density -1
          mass 0.15
        }
        linearVelocity -0.03773651673051557 -0.01661432186548181 3.5209417464040754e-05
        angularVelocity -0.0005025344644055606 -0.002520044880775913 -0.5272758314877078
      }
    }
    DEF BR_HIP HingeJoint {
      jointParameters HingeJointParameters {
        position -0.19549271388323675
        axis 0 0 1
        anchor -0.15 -0.04 -0.09
      }
      device [
        RotationalMotor {
          name "br_hip"
          maxVelocity 6
          maxTorque 20
          minPosition -0.8
          maxPosition 0.8
        }
        PositionSensor {
          name "br_hip_sensor"
        }
      ]
      endPoint Solid {
        translation -0.16359749210607977 -0.10866664553060021 -0.09
        rotation 0 0 -1 0.19549271388323636
        children [
          Shape {
            appearance PBRAppearance {
              baseColor 0.8 0.3 0.1
            }
            geometry Box {
              size 0.03 0.14 0.03
            }
          }
          DEF BR_KNEE HingeJoint {
            jointParameters HingeJointParameters {
              position -0.8664431544431094
              axis 0 0 1
              anchor 0 -0.07 0
            }
            device [
              RotationalMotor {
                name "br_knee"
                maxVelocity 6
                maxTorque 20
                minPosition -1.5
                maxPosition 0.1
              }
              PositionSensor {
                name "br_knee_sensor"
              }
            ]
            endPoint Solid {
              translation -0.05334213910248661 -0.11532787438178599 0
              rotation 0 0 -1 0.8664431544431093
              children [
                Shape {
                  appearance PBRAppearance {
                    baseColor 0.9 0.6 0.1
                  }
                  geometry Box {
                    size 0.025 0.14 0.025
                  }
                }
              ]
              name "br_shin"
              boundingObject Box {
                size 0.04 0.16 0.04
              }
              physics Physics {
                density -1
                mass 0.15
              }
              linearVelocity -0.20225175856176436 0.15152601330808516 -0.0006310973253185873
              angularVelocity -0.0008029804461621613 -0.009112264257558213 -2.0915568599585868
            }
          }
        ]
        name "br_thigh"
        boundingObject Box {
          size 0.03 0.14 0.03
        }
        physics Physics {
          density -1
          mass 0.15
        }
        linearVelocity -0.06863890132746672 0.0028667877312454166 -4.622216610504399e-05
        angularVelocity -0.000592887101235976 -0.004517378330608355 -1.0016110714040038
      }
    }
    Gyro {
    }
    GPS {
    }
    InertialUnit {
      name "imu"
    }
  ]
  name "quadruped"
  boundingObject Box {
    size 0.4 0.08 0.2
  }
  physics Physics {
    density -1
    mass 1.4
  }
  controller "legged_controller"
  linearVelocity -0.003038295538694403 -0.003391010016029843 -2.2050870312204964e-05
  angularVelocity -0.00038786382424467654 1.854977961629929e-05 0.07566880256927667
}
